Workbook

Sheet Логика цен
A1: ЛОГИКА ЦЕНООБРАЗОВАНИЯ — ключевые параметры (жёлтые ячейки редактируешь ты)
A3: Наценка B2B на РАЗОВЫЕ заявки (без подписки) | B3: 0.3 | C3: Безнал = налоги, счета-фактуры, акты, договор, SLA. Разово юрик платит ДОРОЖЕ физика
A4: Наценка за аварийный/ночной вызов | B4: 0.5 | C4: После 20:00, выходные, праздники: +50%; глубокая ночь — можно +100%
A5: Минимальный чек выезда B2C, сум | B5: 100000 | C5: Ниже — заявка убыточна с учётом дороги и доли мастера
A6: Доля мастера от стоимости работ | B6: 0.55 | C6: Коридор 50–60%. Материалы в долю не входят — по чеку
A7: Плановый техосмотр B2B (за один), сум | B7: 300000 | C7: Входит в подписку, база расчёта тарифов
A8: Скидка подписки от цены «B2B разовая» | B8: 0.1 | C8: Подписчик платит на 10% меньше РАЗОВОЙ B2B-цены того же объёма (≈ B2C × 1,17). Дороже розницы физика: скидка юрику — от юрика, не от физика
A9: Ставка НДС (Узбекистан) | B9: 0.12 | C9: Цены каталога — КОНЕЧНЫЕ (с НДС). В счёт-фактуре НДС выделяется изнутри: без НДС = цена / 1,12. Для клиентов-неплательщиков цена та же.
A10: Наценка «Срочно» — платный приоритет клиента | B10: 0.3 | C10: Тариф «Срочно»: +30% только к работам (ТЗ 17.3). Аварийная/ночная/срочная наценки взаимоисключающие — применяется одна наибольшая (ТЗ 3.7). Снимается автоматически, если работы не начаты за 3 ч (правило честности).
A11: ЦЕНОВАЯ ЛОГИКА (три уровня):
A12: 1. B2C — базовый прайс. Оплата Payme/Click/Uzum или карта. Гарантия 30 дней.
A13: 2. B2B разовая = B2C × (1 + наценка) — и «от», и «до» (сейчас +30%). Перечисление, СФ с выделением НДС, договор.
A14: 3. B2B абонентка: фикс. сумма в договоре; работы списываются по подписным ценам = «B2B разовая» × (1 − скидка 10%) ≈ B2C × 1,17. Осмотры входят.
A15: Всё сверх абонентки — отдельная счёт-фактура по ценам «B2B разовая» (+30%). Осмотры входят в абонентку.
A16: Продающий аргумент: «подписка — на 10% дешевле разовых вызовов + SLA + осмотры включены». Розница физика — отдельный мир, юрику недоступна.
A18: ПРАВИЛА ПРАЙСА:
A19: • Цена за РАБОТУ. Материалы отдельно, по чеку, без наценки мастера.
A20: • Цена называется клиенту ДО начала работ. Выход за диапазон — только через диспетчера.
A21: • Выезд + диагностика — по каталогу (позиция 1), при заказе работ — бесплатно.
A22: • Диапазон «от–до»: «от» — типовой случай, «до» — сложный (бетон, высота, демонтаж, старые коммуникации).
A24: НАСКОЛЬКО ДОРОЖЕ/ДЕШЕВЛЕ ДЛЯ БИЗНЕСА (считается формулами):
A25: B2B разовая vs B2C | B25: =B3 | C25: Разово бизнес платит дороже физлица на наценку B3
A26: Подписка vs B2C | B26: =(1+B3)*(1-B8)-1 | C26: Подписка ДОРОЖЕ розницы физика (~+17%), но дешевле разовой юрика
A27: B2B разовая vs подписка (клин продаж) | B27: =1/(1-B8)-1 | C27: Настолько разовая дороже подписной цены — аргумент в подписку

Sheet Каталог услуг
A1: ПОЛНЫЙ КАТАЛОГ УСЛУГ — B2C база, B2B разовая (+30%, с НДС и без), подписка (разовая −10%), доля мастера (Ташкент, июль 2026)
A2: Синие ячейки (B2C от/до, столбцы D–E) калибруешь ты. Остальные — формулы через «Логику цен»: B2B раз. = B2C × (1+B3); без НДС = с НДС / (1+B9); подписка = B2B раз. × (1−B8); мастеру = B2C × B6. Цены конечные (с НДС), в СФ НДС выделяется изнутри. Колонки N–R (нормо-часы, skill-теги, оборудование/парная/этапная) обязательны для импорта в платформу (DEV-02 PriceItem, планировщик слотов ТЗ 17.3) — заполняет владелец, см. DEV-05 п.17.
A4: № | B4: Услуга | C4: Ед. изм. | D4: B2C от (сум) | E4: B2C до (сум) | F4: B2B раз. от (с НДС) | G4: B2B раз. до (с НДС) | H4: B2B раз. от (без НДС) | I4: B2B раз. до (без НДС) | J4: Подписка от (с НДС) | K4: Подписка до (с НДС) | L4: Мастеру от (сум) | M4: Примечание | N4: Нормо-часы | O4: Skill-теги | P4: Требует оборудование (да/нет) | Q4: Парная (да/нет) | R4: Этапная (да/нет)
A5: ВЫЕЗД И ДИАГНОСТИКА
A6: 1 | B6: Выезд мастера + диагностика (бесплатно при заказе работ) | C6: выезд | D6: 150000 | E6: 200000 | F6: =ROUND(D6*(1+'Логика цен'!$B$3),-3) | G6: =ROUND(E6*(1+'Логика цен'!$B$3),-3) | H6: =ROUND(F6/(1+'Логика цен'!$B$9),-3) | I6: =ROUND(G6/(1+'Логика цен'!$B$9),-3) | J6: =ROUND(D6*(1+'Логика цен'!$B$3)*(1-'Логика цен'!$B$8),-3) | K6: =ROUND(E6*(1+'Логика цен'!$B$3)*(1-'Логика цен'!$B$8),-3) | L6: =ROUND(D6*'Логика цен'!$B$6,-3)
A7: 2 | B7: Аварийный выезд (вечер/ночь/выходные) | C7: выезд | D7: 200000 | E7: 250000 | F7: =ROUND(D7*(1+'Логика цен'!$B$3),-3) | G7: =ROUND(E7*(1+'Логика цен'!$B$3),-3) | H7: =ROUND(F7/(1+'Логика цен'!$B$9),-3) | I7: =ROUND(G7/(1+'Логика цен'!$B$9),-3) | J7: =ROUND(D7*(1+'Логика цен'!$B$3)*(1-'Логика цен'!$B$8),-3) | K7: =ROUND(E7*(1+'Логика цен'!$B$3)*(1-'Логика цен'!$B$8),-3) | L7: =ROUND(D7*'Логика цен'!$B$6,-3) | M7: Плюс наценка к работам по коэффициенту
A8: 3 | B8: Технический осмотр помещения по чек-листу | C8: объект | D8: 200000 | E8: 400000 | F8: =ROUND(D8*(1+'Логика цен'!$B$3),-3) | G8: =ROUND(E8*(1+'Логика цен'!$B$3),-3) | H8: =ROUND(F8/(1+'Логика цен'!$B$9),-3) | I8: =ROUND(G8/(1+'Логика цен'!$B$9),-3) | J8: =ROUND(D8*(1+'Логика цен'!$B$3)*(1-'Логика цен'!$B$8),-3) | K8: =ROUND(E8*(1+'Логика цен'!$B$3)*(1-'Логика цен'!$B$8),-3) | L8: =ROUND(D8*'Логика цен'!$B$6,-3) | M8: Для B2B входит в подписку
A9: 4 | B9: Составление дефектной ведомости / сметы работ | C9: объект | D9: 150000 | E9: 300000 | F9: =ROUND(D9*(1+'Логика цен'!$B$3),-3) | G9: =ROUND(E9*(1+'Логика цен'!$B$3),-3) | H9: =ROUND(F9/(1+'Логика цен'!$B$9),-3) | I9: =ROUND(G9/(1+'Логика цен'!$B$9),-3) | J9: =ROUND(D9*(1+'Логика цен'!$B$3)*(1-'Логика цен'!$B$8),-3) | K9: =ROUND(E9*(1+'Логика цен'!$B$3)*(1-'Логика цен'!$B$8),-3) | L9: =ROUND(D9*'Логика цен'!$B$6,-3) | M9: Бесплатно при заказе работ от 1 млн
A10: САНТЕХНИКА
A11: 5 | B11: Установка/замена смесителя | C11: шт | D11: 160000 | E11: 250000 | F11: =ROUND(D11*(1+'Логика цен'!$B$3),-3) | G11: =ROUND(E11*(1+'Логика цен'!$B$3),-3) | H11: =ROUND(F11/(1+'Логика цен'!$B$9),-3) | I11: =ROUND(G11/(1+'Логика цен'!$B$9),-3) | J11: =ROUND(D11*(1+'Логика цен'!$B$3)*(1-'Логика цен'!$B$8),-3) | K11: =ROUND(E11*(1+'Логика цен'!$B$3)*(1-'Логика цен'!$B$8),-3) | L11: =ROUND(D11*'Логика цен'!$B$6,-3)
A12: 6 | B12: Ремонт смесителя (картридж, кран-букса, течь) | C12: шт | D12: 90000 | E12: 150000 | F12: =ROUND(D12*(1+'Логика цен'!$B$3),-3) | G12: =ROUND(E12*(1+'Логика цен'!$B$3),-3) | H12: =ROUND(F12/(1+'Логика цен'!$B$9),-3) | I12: =ROUND(G12/(1+'Логика цен'!$B$9),-3) | J12: =ROUND(D12*(1+'Логика цен'!$B$3)*(1-'Логика цен'!$B$8),-3) | K12: =ROUND(E12*(1+'Логика цен'!$B$3)*(1-'Логика цен'!$B$8),-3) | L12: =ROUND(D12*'Логика цен'!$B$6,-3)
A13: 7 | B13: Установка/замена унитаза | C13: шт | D13: 250000 | E13: 400000 | F13: =ROUND(D13*(1+'Логика цен'!$B$3),-3) | G13: =ROUND(E13*(1+'Логика цен'!$B$3),-3) | H13: =ROUND(F13/(1+'Логика цен'!$B$9),-3) | I13: =ROUND(G13/(1+'Логика цен'!$B$9),-3) | J13: =ROUND(D13*(1+'Логика цен'!$B$3)*(1-'Логика цен'!$B$8),-3) | K13: =ROUND(E13*(1+'Логика цен'!$B$3)*(1-'Логика цен'!$B$8),-3) | L13: =ROUND(D13*'Логика цен'!$B$6,-3) | M13: С демонтажом старого
A14: 8 | B14: Замена арматуры/ремонт бачка | C14: шт | D14: 100000 | E14: 150000 | F14: =ROUND(D14*(1+'Логика цен'!$B$3),-3) | G14: =ROUND(E14*(1+'Логика цен'!$B$3),-3) | H14: =ROUND(F14/(1+'Логика цен'!$B$9),-3) | I14: =ROUND(G14/(1+'Логика цен'!$B$9),-3) | J14: =ROUND(D14*(1+'Логика цен'!$B$3)*(1-'Логика цен'!$B$8),-3) | K14: =ROUND(E14*(1+'Логика цен'!$B$3)*(1-'Логика цен'!$B$8),-3) | L14: =ROUND(D14*'Логика цен'!$B$6,-3)
A15: 9 | B15: Установка инсталляции (подвесной унитаз) | C15: шт | D15: 500000 | E15: 800000 | F15: =ROUND(D15*(1+'Логика цен'!$B$3),-3) | G15: =ROUND(E15*(1+'Логика цен'!$B$3),-3) | H15: =ROUND(F15/(1+'Логика цен'!$B$9),-3) | I15: =ROUND(G15/(1+'Логика цен'!$B$9),-3) | J15: =ROUND(D15*(1+'Логика цен'!$B$3)*(1-'Логика цен'!$B$8),-3) | K15: =ROUND(E15*(1+'Логика цен'!$B$3)*(1-'Логика цен'!$B$8),-3) | L15: =ROUND(D15*'Логика цен'!$B$6,-3)
A16: 10 | B16: Установка раковины/мойки/тюльпана | C16: шт | D16: 250000 | E16: 350000 | F16: =ROUND(D16*(1+'Логика цен'!$B$3),-3) | G16: =ROUND(E16*(1+'Логика цен'!$B$3),-3) | H16: =ROUND(F16/(1+'Логика цен'!$B$9),-3) | I16: =ROUND(G16/(1+'Логика цен'!$B$9),-3) | J16: =ROUND(D16*(1+'Логика цен'!$B$3)*(1-'Логика цен'!$B$8),-3) | K16: =ROUND(E16*(1+'Логика цен'!$B$3)*(1-'Логика цен'!$B$8),-3) | L16: =ROUND(D16*'Логика цен'!$B$6,-3) | M16: С сифоном
A17: 11 | B17: Установка ванны | C17: шт | D17: 400000 | E17: 700000 | F17: =ROUND(D17*(1+'Логика цен'!$B$3),-3) | G17: =ROUND(E17*(1+'Логика цен'!$B$3),-3) | H17: =ROUND(F17/(1+'Логика цен'!$B$9),-3) | I17: =ROUND(G17/(1+'Логика цен'!$B$9),-3) | J17: =ROUND(D17*(1+'Логика цен'!$B$3)*(1-'Логика цен'!$B$8),-3) | K17: =ROUND(E17*(1+'Логика цен'!$B$3)*(1-'Логика цен'!$B$8),-3) | L17: =ROUND(D17*'Логика цен'!$B$6,-3)
A18: 12 | B18: Установка душевой кабины | C18: шт | D18: 500000 | E18: 900000 | F18: =ROUND(D18*(1+'Логика цен'!$B$3),-3) | G18: =ROUND(E18*(1+'Логика цен'!$B$3),-3) | H18: =ROUND(F18/(1+'Логика цен'!$B$9),-3) | I18: =ROUND(G18/(1+'Логика цен'!$B$9),-3) | J18: =ROUND(D18*(1+'Логика цен'!$B$3)*(1-'Логика цен'!$B$8),-3) | K18: =ROUND(E18*(1+'Логика цен'!$B$3)*(1-'Логика цен'!$B$8),-3) | L18: =ROUND(D18*'Логика цен'!$B$6,-3) | M18: Сборка + подключение
A19: 13 | B19: Замена сифона | C19: шт | D19: 90000 | E19: 140000 | F19: =ROUND(D19*(1+'Логика цен'!$B$3),-3) | G19: =ROUND(E19*(1+'Логика цен'!$B$3),-3) | H19: =ROUND(F19/(1+'Логика цен'!$B$9),-3) | I19: =ROUND(G19/(1+'Логика цен'!$B$9),-3) | J19: =ROUND(D19*(1+'Логика цен'!$B$3)*(1-'Логика цен'!$B$8),-3) | K19: =ROUND(E19*(1+'Логика цен'!$B$3)*(1-'Логика цен'!$B$8),-3) | L19: =ROUND(D19*'Логика цен'!$B$6,-3)
A20: 14 | B20: Замена гибкой подводки | C20: шт | D20: 50000 | E20: 80000 | F20: =ROUND(D20*(1+'Логика цен'!$B$3),-3) | G20: =ROUND(E20*(1+'Логика цен'!$B$3),-3) | H20: =ROUND(F20/(1+'Логика цен'!$B$9),-3) | I20: =ROUND(G20/(1+'Логика цен'!$B$9),-3) | J20: =ROUND(D20*(1+'Логика цен'!$B$3)*(1-'Логика цен'!$B$8),-3) | K20: =ROUND(E20*(1+'Логика цен'!$B$3)*(1-'Логика цен'!$B$8),-3) | L20: =ROUND(D20*'Логика цен'!$B$6,-3)
A21: 15 | B21: Установка/замена шарового крана | C21: шт | D21: 120000 | E21: 150000 | F21: =ROUND(D21*(1+'Логика цен'!$B$3),-3) | G21: =ROUND(E21*(1+'Логика цен'!$B$3),-3) | H21: =ROUND(F21/(1+'Логика цен'!$B$9),-3) | I21: =ROUND(G21/(1+'Логика цен'!$B$9),-3) | J21: =ROUND(D21*(1+'Логика цен'!$B$3)*(1-'Логика цен'!$B$8),-3) | K21: =ROUND(E21*(1+'Логика цен'!$B$3)*(1-'Логика цен'!$B$8),-3) | L21: =ROUND(D21*'Логика цен'!$B$6,-3) | M21: Может требовать отключения стояка
A22: 16 | B22: Прочистка локального засора (раковина/ванна) | C22: точка | D22: 150000 | E22: 1000000 | F22: =ROUND(D22*(1+'Логика цен'!$B$3),-3) | G22: =ROUND(E22*(1+'Логика цен'!$B$3),-3) | H22: =ROUND(F22/(1+'Логика цен'!$B$9),-3) | I22: =ROUND(G22/(1+'Логика цен'!$B$9),-3) | J22: =ROUND(D22*(1+'Логика цен'!$B$3)*(1-'Логика цен'!$B$8),-3) | K22: =ROUND(E22*(1+'Логика цен'!$B$3)*(1-'Логика цен'!$B$8),-3) | L22: =ROUND(D22*'Логика цен'!$B$6,-3)
A23: 17 | B23: Прочистка канализации (стояк, трос до 10 м) | C23: точка | D23: 120000 | E23: 250000 | F23: =ROUND(D23*(1+'Логика цен'!$B$3),-3) | G23: =ROUND(E23*(1+'Логика цен'!$B$3),-3) | H23: =ROUND(F23/(1+'Логика цен'!$B$9),-3) | I23: =ROUND(G23/(1+'Логика цен'!$B$9),-3) | J23: =ROUND(D23*(1+'Логика цен'!$B$3)*(1-'Логика цен'!$B$8),-3) | K23: =ROUND(E23*(1+'Логика цен'!$B$3)*(1-'Логика цен'!$B$8),-3) | L23: =ROUND(D23*'Логика цен'!$B$6,-3)
A24: 18 | B24: Замена участка трубы водоснабжения (ППР, пайка) | C24: п.м | D24: 120000 | E24: 200000 | F24: =ROUND(D24*(1+'Логика цен'!$B$3),-3) | G24: =ROUND(E24*(1+'Логика цен'!$B$3),-3) | H24: =ROUND(F24/(1+'Логика цен'!$B$9),-3) | I24: =ROUND(G24/(1+'Логика цен'!$B$9),-3) | J24: =ROUND(D24*(1+'Логика цен'!$B$3)*(1-'Логика цен'!$B$8),-3) | K24: =ROUND(E24*(1+'Логика цен'!$B$3)*(1-'Логика цен'!$B$8),-3) | L24: =ROUND(D24*'Логика цен'!$B$6,-3)
A25: 19 | B25: Замена канализационной трубы | C25: п.м | D25: 100000 | E25: 280000 | F25: =ROUND(D25*(1+'Логика цен'!$B$3),-3) | G25: =ROUND(E25*(1+'Логика цен'!$B$3),-3) | H25: =ROUND(F25/(1+'Логика цен'!$B$9),-3) | I25: =ROUND(G25/(1+'Логика цен'!$B$9),-3) | J25: =ROUND(D25*(1+'Логика цен'!$B$3)*(1-'Логика цен'!$B$8),-3) | K25: =ROUND(E25*(1+'Логика цен'!$B$3)*(1-'Логика цен'!$B$8),-3) | L25: =ROUND(D25*'Логика цен'!$B$6,-3)
A26: 20 | B26: Врезка в существующую трубу (отвод) | C26: точка | D26: 120000 | E26: 250000 | F26: =ROUND(D26*(1+'Логика цен'!$B$3),-3) | G26: =ROUND(E26*(1+'Логика цен'!$B$3),-3) | H26: =ROUND(F26/(1+'Логика цен'!$B$9),-3) | I26: =ROUND(G26/(1+'Логика цен'!$B$9),-3) | J26: =ROUND(D26*(1+'Логика цен'!$B$3)*(1-'Логика цен'!$B$8),-3) | K26: =ROUND(E26*(1+'Логика цен'!$B$3)*(1-'Логика цен'!$B$8),-3) | L26: =ROUND(D26*'Логика цен'!$B$6,-3)
A27: 21 | B27: Установка фильтра воды / редуктора давления | C27: шт | D27: 100000 | E27: 200000 | F27: =ROUND(D27*(1+'Логика цен'!$B$3),-3) | G27: =ROUND(E27*(1+'Логика цен'!$B$3),-3) | H27: =ROUND(F27/(1+'Логика цен'!$B$9),-3) | I27: =ROUND(G27/(1+'Логика цен'!$B$9),-3) | J27: =ROUND(D27*(1+'Логика цен'!$B$3)*(1-'Логика цен'!$B$8),-3) | K27: =ROUND(E27*(1+'Логика цен'!$B$3)*(1-'Логика цен'!$B$8),-3) | L27: =ROUND(D27*'Логика цен'!$B$6,-3)
A28: 22 | B28: Установка счётчика воды (без опломбировки) | C28: шт | D28: 150000 | E28: 250000 | F28: =ROUND(D28*(1+'Логика цен'!$B$3),-3) | G28: =ROUND(E28*(1+'Логика цен'!$B$3),-3) | H28: =ROUND(F28/(1+'Логика цен'!$B$9),-3) | I28: =ROUND(G28/(1+'Логика цен'!$B$9),-3) | J28: =ROUND(D28*(1+'Логика цен'!$B$3)*(1-'Логика цен'!$B$8),-3) | K28: =ROUND(E28*(1+'Логика цен'!$B$3)*(1-'Логика цен'!$B$8),-3) | L28: =ROUND(D28*'Логика цен'!$B$6,-3) | M28: Опломбировка — через водоканал
A29: 23 | B29: Установка/замена радиатора отопления | C29: шт | D29: 300000 | E29: 500000 | F29: =ROUND(D29*(1+'Логика цен'!$B$3),-3) | G29: =ROUND(E29*(1+'Логика цен'!$B$3),-3) | H29: =ROUND(F29/(1+'Логика цен'!$B$9),-3) | I29: =ROUND(G29/(1+'Логика цен'!$B$9),-3) | J29: =ROUND(D29*(1+'Логика цен'!$B$3)*(1-'Логика цен'!$B$8),-3) | K29: =ROUND(E29*(1+'Логика цен'!$B$3)*(1-'Логика цен'!$B$8),-3) | L29: =ROUND(D29*'Логика цен'!$B$6,-3)
A30: 24 | B30: Промывка радиатора/системы отопления | C30: шт | D30: 250000 | E30: 450000 | F30: =ROUND(D30*(1+'Логика цен'!$B$3),-3) | G30: =ROUND(E30*(1+'Логика цен'!$B$3),-3) | H30: =ROUND(F30/(1+'Логика цен'!$B$9),-3) | I30: =ROUND(G30/(1+'Логика цен'!$B$9),-3) | J30: =ROUND(D30*(1+'Логика цен'!$B$3)*(1-'Логика цен'!$B$8),-3) | K30: =ROUND(E30*(1+'Логика цен'!$B$3)*(1-'Логика цен'!$B$8),-3) | L30: =ROUND(D30*'Логика цен'!$B$6,-3) | M30: Сезон: осень
A31: 25 | B31: Установка полотенцесушителя | C31: шт | D31: 250000 | E31: 450000 | F31: =ROUND(D31*(1+'Логика цен'!$B$3),-3) | G31: =ROUND(E31*(1+'Логика цен'!$B$3),-3) | H31: =ROUND(F31/(1+'Логика цен'!$B$9),-3) | I31: =ROUND(G31/(1+'Логика цен'!$B$9),-3) | J31: =ROUND(D31*(1+'Логика цен'!$B$3)*(1-'Логика цен'!$B$8),-3) | K31: =ROUND(E31*(1+'Логика цен'!$B$3)*(1-'Логика цен'!$B$8),-3) | L31: =ROUND(D31*'Логика цен'!$B$6,-3)
A32: 26 | B32: Установка водонагревателя | C32: шт | D32: 250000 | E32: 450000 | F32: =ROUND(D32*(1+'Логика цен'!$B$3),-3) | G32: =ROUND(E32*(1+'Логика цен'!$B$3),-3) | H32: =ROUND(F32/(1+'Логика цен'!$B$9),-3) | I32: =ROUND(G32/(1+'Логика цен'!$B$9),-3) | J32: =ROUND(D32*(1+'Логика цен'!$B$3)*(1-'Логика цен'!$B$8),-3) | K32: =ROUND(E32*(1+'Логика цен'!$B$3)*(1-'Логика цен'!$B$8),-3) | L32: =ROUND(D32*'Логика цен'!$B$6,-3)
A33: 27 | B33: Подключение стиральной/посудомоечной машины | C33: шт | D33: 150000 | E33: 350000 | F33: =ROUND(D33*(1+'Логика цен'!$B$3),-3) | G33: =ROUND(E33*(1+'Логика цен'!$B$3),-3) | H33: =ROUND(F33/(1+'Логика цен'!$B$9),-3) | I33: =ROUND(G33/(1+'Логика цен'!$B$9),-3) | J33: =ROUND(D33*(1+'Логика цен'!$B$3)*(1-'Логика цен'!$B$8),-3) | K33: =ROUND(E33*(1+'Логика цен'!$B$3)*(1-'Логика цен'!$B$8),-3) | L33: =ROUND(D33*'Логика цен'!$B$6,-3)
A34: 28 | B34: Герметизация ванны/душа/стыков | C34: п.м | D34: 20000 | E34: 70000 | F34: =ROUND(D34*(1+'Логика цен'!$B$3),-3) | G34: =ROUND(E34*(1+'Логика цен'!$B$3),-3) | H34: =ROUND(F34/(1+'Логика цен'!$B$9),-3) | I34: =ROUND(G34/(1+'Логика цен'!$B$9),-3) | J34: =ROUND(D34*(1+'Логика цен'!$B$3)*(1-'Логика цен'!$B$8),-3) | K34: =ROUND(E34*(1+'Логика цен'!$B$3)*(1-'Логика цен'!$B$8),-3) | L34: =ROUND(D34*'Логика цен'!$B$6,-3)
A35: ЭЛЕКТРИКА
A36: 29 | B36: Установка/замена розетки/выключателя (в готовое место) | C36: точка | D36: 70000 | E36: 150000 | F36: =ROUND(D36*(1+'Логика цен'!$B$3),-3) | G36: =ROUND(E36*(1+'Логика цен'!$B$3),-3) | H36: =ROUND(F36/(1+'Логика цен'!$B$9),-3) | I36: =ROUND(G36/(1+'Логика цен'!$B$9),-3) | J36: =ROUND(D36*(1+'Логика цен'!$B$3)*(1-'Логика цен'!$B$8),-3) | K36: =ROUND(E36*(1+'Логика цен'!$B$3)*(1-'Логика цен'!$B$8),-3) | L36: =ROUND(D36*'Логика цен'!$B$6,-3)
A37: 30 | B37: Перенос розетки/выключателя | C37: точка | D37: 150000 | E37: 550000 | F37: =ROUND(D37*(1+'Логика цен'!$B$3),-3) | G37: =ROUND(E37*(1+'Логика цен'!$B$3),-3) | H37: =ROUND(F37/(1+'Логика цен'!$B$9),-3) | I37: =ROUND(G37/(1+'Логика цен'!$B$9),-3) | J37: =ROUND(D37*(1+'Логика цен'!$B$3)*(1-'Логика цен'!$B$8),-3) | K37: =ROUND(E37*(1+'Логика цен'!$B$3)*(1-'Логика цен'!$B$8),-3) | L37: =ROUND(D37*'Логика цен'!$B$6,-3) | M37: Со штробой и кабелем 1м
A38: 31 | B38: Монтаж новой точки (подрозетник + штроба до 1 м) | C38: точка | D38: 150000 | E38: 280000 | F38: =ROUND(D38*(1+'Логика цен'!$B$3),-3) | G38: =ROUND(E38*(1+'Логика цен'!$B$3),-3) | H38: =ROUND(F38/(1+'Логика цен'!$B$9),-3) | I38: =ROUND(G38/(1+'Логика цен'!$B$9),-3) | J38: =ROUND(D38*(1+'Логика цен'!$B$3)*(1-'Логика цен'!$B$8),-3) | K38: =ROUND(E38*(1+'Логика цен'!$B$3)*(1-'Логика цен'!$B$8),-3) | L38: =ROUND(D38*'Логика цен'!$B$6,-3) | M38: Бетон дороже
A39: 32 | B39: Установка диммера/терморегулятора | C39: шт | D39: 90000 | E39: 180000 | F39: =ROUND(D39*(1+'Логика цен'!$B$3),-3) | G39: =ROUND(E39*(1+'Логика цен'!$B$3),-3) | H39: =ROUND(F39/(1+'Логика цен'!$B$9),-3) | I39: =ROUND(G39/(1+'Логика цен'!$B$9),-3) | J39: =ROUND(D39*(1+'Логика цен'!$B$3)*(1-'Логика цен'!$B$8),-3) | K39: =ROUND(E39*(1+'Логика цен'!$B$3)*(1-'Логика цен'!$B$8),-3) | L39: =ROUND(D39*'Логика цен'!$B$6,-3)
A40: 33 | B40: Установка люстры | C40: шт | D40: 200000 | E40: 350000 | F40: =ROUND(D40*(1+'Логика цен'!$B$3),-3) | G40: =ROUND(E40*(1+'Логика цен'!$B$3),-3) | H40: =ROUND(F40/(1+'Логика цен'!$B$9),-3) | I40: =ROUND(G40/(1+'Логика цен'!$B$9),-3) | J40: =ROUND(D40*(1+'Логика цен'!$B$3)*(1-'Логика цен'!$B$8),-3) | K40: =ROUND(E40*(1+'Логика цен'!$B$3)*(1-'Логика цен'!$B$8),-3) | L40: =ROUND(D40*'Логика цен'!$B$6,-3)
A41: 34 | B41: Установка люстры с монтажом крюка/планки в бетон | C41: шт | D41: 250000 | E41: 450000 | F41: =ROUND(D41*(1+'Логика цен'!$B$3),-3) | G41: =ROUND(E41*(1+'Логика цен'!$B$3),-3) | H41: =ROUND(F41/(1+'Логика цен'!$B$9),-3) | I41: =ROUND(G41/(1+'Логика цен'!$B$9),-3) | J41: =ROUND(D41*(1+'Логика цен'!$B$3)*(1-'Логика цен'!$B$8),-3) | K41: =ROUND(E41*(1+'Логика цен'!$B$3)*(1-'Логика цен'!$B$8),-3) | L41: =ROUND(D41*'Логика цен'!$B$6,-3)
...

Sheet B2B абонентка
A1: B2B: АБОНЕНТСКАЯ МОДЕЛЬ — фикс в договоре, сверх лимита отдельной счёт-фактурой
A3: Механика: клиент платит фикс. сумму в месяц. Работы списываются из неё по подписным ценам («B2B разовая» − 10%). Осмотры входят. Всё сверх суммы — отдельная СФ по ценам «B2B разовая» (+30% к B2C, без скидки).
A5: Параметр | B5: Базовый | C5: Стандарт | D5: Про | F5: Комментарий
A6: Целевой клиент | B6: Небольшой офис, магазин | C6: Кафе, салон, средний офис | D6: Ресторан, гостиница, сеть
A7: АБОНЕНТСКАЯ СУММА в договоре, сум/мес | B7: 1500000 | C7: 3000000 | D7: 5000000 | F7: Жёлтое: твоя цена в договоре
A8: Средний чек заявки по B2C-прайсу, сум | B8: 200000 | C8: 220000 | D8: 250000 | F8: У Про выше: кондиционеры, вентиляция, сварка
A9: Плановых осмотров в месяц | B9: 1 | C9: 1 | D9: 2
A10: Осмотры (списываются из абонентки), сум/мес | B10: =B9*'Логика цен'!$B$7 | C10: =C9*'Логика цен'!$B$7 | D10: =D9*'Логика цен'!$B$7
A11: Остаток абонентки на заявки, сум/мес | B11: =B7-B10 | C11: =C7-C10 | D11: =D7-D10
A12: Подписной средний чек («B2B разовая» − 10%), сум | B12: =ROUND(B8*(1+'Логика цен'!$B$3)*(1-'Логика цен'!$B$8),-3) | C12: =ROUND(C8*(1+'Логика цен'!$B$3)*(1-'Логика цен'!$B$8),-3) | D12: =ROUND(D8*(1+'Логика цен'!$B$3)*(1-'Логика цен'!$B$8),-3)
A13: ПОКРЫВАЕТ ЗАЯВОК В МЕСЯЦ, шт ≈ | B13: =ROUND(B11/B12,0) | C13: =ROUND(C11/C12,0) | D13: =ROUND(D11/D12,0)
A14: Те же работы по разовым B2B-ценам, сум/мес | B14: =ROUND((B13*B8+B9*'Логика цен'!$B$7)*(1+'Логика цен'!$B$3),-4) | C14: =ROUND((C13*C8+C9*'Логика цен'!$B$7)*(1+'Логика цен'!$B$3),-4) | D14: =ROUND((D13*D8+D9*'Логика цен'!$B$7)*(1+'Логика цен'!$B$3),-4)
A15: Выгода клиента от абонентки, сум/мес | B15: =B14-B7 | C15: =C14-C7 | D15: =D14-D7
A16: Выгода клиента, % | B16: =(B14-B7)/B14 | C16: =(C14-C7)/C14 | D16: =(D14-D7)/D14
A18: УСЛОВИЯ ДОГОВОРА (проект):
A19: • Работы учитываются по подписным ценам = «B2B разовая» × (1 − скидка с листа «Логика цен», B8).
A20: • Всё СВЕРХ абонентской суммы — отдельная счёт-фактура в конце месяца по ценам «B2B разовая» (+30%).
A21: • Неиспользованный остаток не переносится. (Вариант для переговоров: переносится до 20% на следующий месяц.)
A22: • Материалы всегда отдельно: по чеку, закрываются той же СФ.
A23: • Время реакции: Базовый — в течение дня, Стандарт — 4 часа, Про — 2 часа.
A24: • Договор от 6 месяцев, оплата абонентки авансом до 5 числа.
A25: • Все суммы (абонентка, СФ сверх лимита) — конечные, с НДС; в СФ НДС 12% выделяется изнутри (лист «Логика цен», B9).
A27: РЕГЛАМЕНТ ПЛАНОВОГО ОСМОТРА (входит): сантехника на течи, протяжка контактов в щитке, замена перегоревших
A28: ламп (лампы клиента), чистка фильтров кондиционеров (в сезон), осмотр вентиляции, проверка дверей/окон/замков,
A29: мелкий крепёж, фотоотчёт о состоянии объекта.
